Workbook

Sheet Dashboard
A1: BÁO CÁO TIẾN ĐỘ DỰ ÁN - TIÊN PHONG CDS
A2: CTO Project Status Report
A3: Kỳ báo cáo: | B3: Tháng 3 | C3: Ngày tạo: | D3: =TODAY() -> 46095
B4: 2026
A6: TỔNG QUAN DỰ ÁN
A7: =COUNTA('Danh Sách Dự Án'!B5:B10) -> 6 | C7: =COUNTIF('Danh Sách Dự Án'!I5:I10,"On Track") -> 3 | E7: =COUNTIF('Danh Sách Dự Án'!I5:I10,"At Risk") -> 0 | G7: =COUNTIF('Danh Sách Dự Án'!I5:I10,"Delayed") -> 2 | I7: =COUNTIF('Danh Sách Dự Án'!I5:I10,"Completed") -> 0 | K7: ='Danh Sách Dự Án'!K11 -> 0.35833333
A9: Tổng Dự Án | C9: On Track | E9: At Risk | G9: Delayed | I9: Completed | K9: % HT Trung Bình
A11: TỔNG QUAN TÀI CHÍNH
A12: ='Danh Sách Dự Án'!M11 -> 11293500000 | D12: ='Danh Sách Dự Án'!N11 -> 344500000 | G12: ='Danh Sách Dự Án'!O11 -> 10949000000 | J12: ='Danh Sách Dự Án'!P11 -> 0.030504272
A14: Tổng Giá Trị HĐ (VNĐ) | D14: Đã Thu (VNĐ) | G14: Còn Phải Thu (VNĐ) | J14: % Đã Thanh Toán
A16: RỦI RO & NHÂN SỰ
A17: ='Rủi Ro & Vấn Đề'!B14 -> 8 | D17: ='Rủi Ro & Vấn Đề'!B15 -> 2 | G17: ='Danh Sách Dự Án'!Q11 -> 55 | J17: ='Nhân Sự Dự Án'!H25 -> 0.94104167
A19: Tổng Rủi Ro | D19: Critical | G19: Tổng Nhân Sự | J19: Utilization Rate TB
A21: Trạng Thái | B21: Số lượng
A22: On Track | B22: =COUNTIF('Danh Sách Dự Án'!I5:I10,"On Track") -> 3
A23: At Risk | B23: =COUNTIF('Danh Sách Dự Án'!I5:I10,"At Risk") -> 0
A24: Delayed | B24: =COUNTIF('Danh Sách Dự Án'!I5:I10,"Delayed") -> 2
A25: Completed | B25: =COUNTIF('Danh Sách Dự Án'!I5:I10,"Completed") -> 0

Sheet Danh Sách Dự Án
A1: BÁO CÁO TỔNG HỢP DỰ ÁN - TIÊN PHONG CDS
A2: =IF(Dashboard!B3<>"",Dashboard!B3&" - "&Dashboard!B4,"") -> Tháng 3 - 2026
A4: STT | B4: Mã DA | C4: Tên Dự Án | D4: Khách Hàng | E4: PM Phụ Trách | F4: Ngày BĐ | G4: Ngày KT (KH) | H4: Ngày KT (TT) | I4: Trạng Thái | J4: % HT Kế Hoạch | K4: % HT Thực Tế | L4: Chênh Lệch | M4: Giá Trị HĐ (VNĐ) | N4: Đã Thanh Toán (VNĐ) | O4: Còn Lại (VNĐ) | P4: % Thanh Toán | Q4: Số Nhân Sự | R4: Mức Ưu Tiên | S4: Ghi Chú
A5: 1 | B5: CDS-2026-001 | C5: SmartShop - Sàn giao dịch TMDT | D5: SmartNet | E5: Thái Hoàng Mai Học | F5: 46030 | G5: 46142 | I5: On Track | J5: =IF(I5="Completed",1,MIN(1,MAX(0,(TODAY()-F5)/(G5-F5)))) -> 0.58035714 | K5: 0.4 | L5: =K5-J5 -> -0.18035714 | M5: 315000000 | N5: 94500000 | O5: =M5-N5 -> 220500000 | P5: =IF(M5=0,0,N5/M5) -> 0.3 | Q5: 10 | R5: High | S5: Phase 2 đang triển khai https://docs.google.com/spreadsheets/d/14lUS48-bgq5VzhtSzPtCaszZI8IwNMY9/edit?gid=1436417658#gid=1436417658
A6: 2 | B6: CDS-2026-002 | C6: Novagroup - Nền tảng eSales & eMarketing | D6: Nova Group | E6: Thái Hoàng Mai Học | F6: 46083 | G6: 46325 | I6: On Track | J6: =IF(I6="Completed",1,MIN(1,MAX(0,(TODAY()-F6)/(G6-F6)))) -> 0.049586777 | K6: 0.1 | L6: =K6-J6 -> 0.050413223 | M6: 7812500000 | O6: =M6-N6 -> 7812500000 | P6: =IF(M6=0,0,N6/M6) -> 0 | Q6: 20 | R6: Critical | S6: Đang trong giai đoạn phân tích & khảo sát Phía BoD của Nova đang process hợp đồng, khi ký sẽ tiến hành thanh toán đợt 1 trong 15 ngày sau ký HD - 20% tương đương (1.262.500.000 - tạm ứng chưa XHD)
A7: 3 | B7: CDS-2026-003 | C7: DuLichViet | D7: CÔNG TY CỔ PHẦN TRUYỀN THÔNG DU LỊCH VIỆT | E7: Thái Hoàng Mai Học | F7: 46357 | I7: Delayed | J7: =IF(I7="Completed",1,MIN(1,MAX(0,(TODAY()-F7)/(G7-F7)))) -> 0.0056517894 | K7: 0.1 | L7: =K7-J7 -> 0.094348211 | M7: 866000000 | N7: 0 | O7: =M7-N7 -> 866000000 | P7: =IF(M7=0,0,N7/M7) -> 0 | Q7: 10 | R7: Medium | S7: Đã gửi hợp đồng & giải pháp, khách hàng chưa chốt
A8: 4 | B8: CDS-2026-004 | C8: VietNamFoodMap - VCCA | D8: Hiệp hội Văn Hóa Ẩm Thực Việt Nam | E8: Thái Hoàng Mai Học | F8: 45681 | G8: 46387 | H8: 46101 | I8: Delayed | J8: =IF(I8="Completed",1,MIN(1,MAX(0,(TODAY()-F8)/(G8-F8)))) -> 0.58640227 | K8: 0.6 | L8: =K8-J8 -> 0.013597734 | M8: 2300000000 | N8: 250000000 | O8: =M8-N8 -> 2050000000 | P8: =IF(M8=0,0,N8/M8) -> 0.10869565 | Q8: 3 | R8: Medium | S8: Đang trong giai đoạn tổng hợp các thông tin nghiệm thu để yêu cầu Vietravel nghiệm thu theo tiến độ (250tr tiếp theo của giai đoạn 1). Sau đó sẽ đi theo kế hoạch mới, có sự tham gia tiếp tục của Vietravel
A9: 5 | B9: CDS-2026-005 | C9: TPX - Sàn TMDT công nghệ | D9: TPCOMS – Công ty Cổ phần Công nghệ Tiên Phát | E9: Nguyễn Diên Sỹ Đạo | F9: 46063 | I9: On Hold | J9: =IF(I9="Completed",1,MIN(1,MAX(0,(TODAY()-F9)/(G9-F9)))) -> 0 | K9: 0.6 | L9: =K9-J9 -> 0.6 | O9: =M9-N9 -> 0 | P9: =IF(M9=0,0,N9/M9) -> 0 | Q9: 7 | R9: Medium | S9: Đang trong giai đoạn demo & PoC, dự án này vừa là khách hàng vừa là nhà đầu tư dự kiến
A10: 6 | B10: CDS-2026-006 | C10: AI Code - R&D | D10: Nội bộ | E10: Đinh Lê Trung Hiếu | F10: 46037 | G10: 46218 | I10: On Track | J10: =IF(I10="Completed",1,MIN(1,MAX(0,(TODAY()-F10)/(G10-F10)))) -> 0.32044199 | K10: 0.35 | L10: =K10-J10 -> 0.029558011 | O10: =M10-N10 -> 0 | P10: =IF(M10=0,0,N10/M10) -> 0 | Q10: 5 | R10: High | S10: Dự án cốt lỗi sử dụng AI đi full quy trình, là bệ phóng cho các dự án sau này, nếu dự án này triển khai thành công, các dự án sau sẽ được tối ưu về hiệu suất và tốc độ
A11: TỔNG CỘNG | J11: =AVERAGE(J5:J10) -> 0.25707333 | K11: =AVERAGE(K5:K10) -> 0.35833333 | M11: =SUM(M5:M10) -> 11293500000 | N11: =SUM(N5:N10) -> 344500000 | O11: =SUM(O5:O10) -> 10949000000 | P11: =IF(M11=0,0,N11/M11) -> 0.030504272 | Q11: =SUM(Q5:Q10) -> 55

Sheet Tiến Độ Hợp Đồng
A1: THEO DÕI TIẾN ĐỘ THANH TOÁN HỢP ĐỒNG
A3: STT | B3: Mã DA | C3: Tên Dự Án | D3: Khách Hàng | E3: Giá Trị HĐ (VNĐ) | F3: Đợt 1 - Số Tiền | G3: Đợt 1 - Ngày DK | H3: Đợt 1 - Ngày TT | I3: Đợt 1 - TT | J3: Đợt 2 - Số Tiền | K3: Đợt 2 - Ngày DK | L3: Đợt 2 - Ngày TT | M3: Đợt 2 - TT | N3: Đợt 3 - Số Tiền | O3: Đợt 3 - Ngày DK | P3: Đợt 3 - Ngày TT | Q3: Đợt 3 - TT | R3: Đợt 4 - Số Tiền | S3: Đợt 4 - Ngày DK | T3: Đợt 4 - Ngày TT | U3: Đợt 4 - TT | V3: Tổng Đã Thu (VNĐ) | W3: Tổng Còn Thu (VNĐ) | X3: % Thu
A4: 1 | B4: CDS-2026-001 | C4: SmartShop - Sàn giao dịch TMDT | D4: SmartNet | E4: 315000000 | F4: 94500000 | I4: Đã thanh toán | J4: 189000000 | K4: 46142 | M4: Chưa đến hạn | N4: 31500000 | O4: 46507 | Q4: Chưa đến hạn | V4: =SUMPRODUCT((I4="Đã thanh toán")*F4)+SUMPRODUCT((M4="Đã thanh toán")*J4)+SUMPRODUCT((Q4="Đã thanh toán")*N4) + SUMPRODUCT((U4="Đã thanh toán")*R4) -> 94500000 | W4: =E4-V4 -> 220500000 | X4: =IF(E4=0,0,V4/E4) -> 0.3
A5: 2 | B5: CDS-2026-002 | C5: Novagroup - Nền tảng eSales & eMarketing | D5: Nova Group | E5: 7812500000 | F5: 1262500000 | G5: 46096 | I5: Chờ thanh toán | J5: 3787500000 | K5: 46356 | M5: Chờ thanh toán | N5: 2113250000 | O5: 46417 | Q5: Chưa đến hạn | R5: 631250000 | S5: 30/02/2028 | U5: Chưa đến hạn | V5: =SUMPRODUCT((I5="Đã thanh toán")*F5)+SUMPRODUCT((M5="Đã thanh toán")*J5)+SUMPRODUCT((Q5="Đã thanh toán")*N5) + SUMPRODUCT((U5="Đã thanh toán")*R5) -> 0 | W5: =E5-V5 -> 7812500000 | X5: =IF(E5=0,0,V5/E5) -> 0
A6: 3 | B6: CDS-2026-003 | C6: DuLichViet | D6: CÔNG TY CỔ PHẦN TRUYỀN THÔNG DU LỊCH VIỆT | E6: 866000000 | F6: 281200000 | G6: 46111 | I6: Chưa đến hạn | J6: 367800000 | K6: 46143 | M6: Chưa đến hạn | N6: 303100000 | O6: 46296 | Q6: Chưa đến hạn | R6: 129900000 | S6: 46661 | U6: Chưa đến hạn | V6: =SUMPRODUCT((I6="Đã thanh toán")*F6)+SUMPRODUCT((M6="Đã thanh toán")*J6)+SUMPRODUCT((Q6="Đã thanh toán")*N6) + SUMPRODUCT((U6="Đã thanh toán")*R6) -> 0 | W6: =E6-V6 -> 866000000 | X6: =IF(E6=0,0,V6/E6) -> 0
A7: 4 | B7: CDS-2026-004 | C7: VietNamFoodMap - VCCA | D7: Hiệp hội Văn Hóa Ẩm Thực Việt Nam | E7: 2300000000 | F7: 250000000 | I7: Đã thanh toán | J7: 250000000 | K7: 46111 | M7: Chờ thanh toán | O7: 46112 | Q7: Chưa đến hạn | V7: =SUMPRODUCT((I7="Đã thanh toán")*F7)+SUMPRODUCT((M7="Đã thanh toán")*J7)+SUMPRODUCT((Q7="Đã thanh toán")*N7) + SUMPRODUCT((U7="Đã thanh toán")*R7) -> 250000000 | W7: =E7-V7 -> 2050000000 | X7: =IF(E7=0,0,V7/E7) -> 0.10869565
A8: 5 | B8: CDS-2026-005 | C8: TPX - Sàn TMDT công nghệ | D8: TPCOMS – Công ty Cổ phần Công nghệ Tiên Phát | I8: Chưa đến hạn | M8: Chưa đến hạn | Q8: Chưa đến hạn | V8: =SUMPRODUCT((I8="Đã thanh toán")*F8)+SUMPRODUCT((M8="Đã thanh toán")*J8)+SUMPRODUCT((Q8="Đã thanh toán")*N8) + SUMPRODUCT((U8="Đã thanh toán")*R8) -> 0 | W8: =E8-V8 -> 0 | X8: =IF(E8=0,0,V8/E8) -> 0
A9: TỔNG CỘNG | E9: =SUM(E4:E8) -> 11293500000 | F9: =SUM(F4:F8) -> 1888200000 | J9: =SUM(J4:J8) -> 4594300000 | N9: =SUM(N4:N8) -> 2447850000 | V9: =SUM(V4:V8) -> 344500000 | W9: =SUM(W4:W8) -> 10949000000 | X9: =IF(E9=0,0,V9/E9) -> 0.030504272

Sheet Nhân Sự Dự Án
A1: PHÂN BỔ NHÂN SỰ DỰ ÁN
A3: STT | B3: Họ Tên | C3: Vị Trí | D3: Dự Án | E3: Vai Trò Trong DA | F3: Giờ Phân Bổ/Tuần | G3: Giờ Thực Tế/Tuần | H3: Utilization Rate | I3: Trạng Thái | J3: Ghi Chú
A4: 1 | B4: Thái Hoàng Mai Học | C4: CTO | D4: CDS-2026-001 | E4: Project Manager | F4: 40 | G4: 42 | H4: =IF(F4=0,0,G4/F4) -> 1.05 | I4: Active | J4: Lead PM
A5: 2 | B5: Nguyễn Hoàng Khan | C5: AI Engineer | D5: CDS-2026-002 | E5: AI Engineer | F5: 40 | G5: 0 | H5: =IF(F5=0,0,G5/F5) -> 0 | I5: Overloaded | J5: Cần hỗ trợ
A6: 3 | B6: Lê Trần Anh Quí | C6: Data Engineer | D6: CDS-2026-002 | E6: Tech Lead | F6: 40 | G6: 38 | H6: =IF(F6=0,0,G6/F6) -> 0.95 | I6: Available | J6: DA đã hoàn thành
A7: 4 | B7: Chung Chí Lâm | C7: Frontend Dev | D7: CDS-2026-005 | E7: Project Manager | F7: 40 | G7: 48 | H7: =IF(F7=0,0,G7/F7) -> 1.2 | I7: Overloaded | J7: Thiếu resource
A8: 5 | B8: Nguyễn Quang Khải | C8: AI Engineer | D8: CDS-2026-006 | E8: Tech Lead | F8: 40 | G8: 40 | H8: =IF(F8=0,0,G8/F8) -> 1 | I8: Active
A9: 6 | B9: Trịnh Hữu Thoại | C9: Backend Dev | D9: CDS-2026-007 | E9: Tech Lead | F9: 40 | G9: 36 | H9: =IF(F9=0,0,G9/F9) -> 0.9 | I9: Active | J9: Mới join
A10: 7 | B10: Hà Nhật Vềnh | C10: Frontend Dev | D10: CDS-2026-006 | E10: Developer | F10: 40 | G10: 38 | H10: =IF(F10=0,0,G10/F10) -> 0.95 | I10: Active
A11: 8 | B11: Nguyễn Nhất Sang | C11: BA | D11: CDS-2026-002 | E11: Business Analyst | F11: 40 | G11: 44 | H11: =IF(F11=0,0,G11/F11) -> 1.1 | I11: Overloaded | J11: Hỗ trợ thêm DA005
A12: 9 | B12: Đinh Lê Trung Hiếu | C12: AI Engineer (Leader) | D12: CDS-2026-001 | E12: QA Engineer | F12: 24 | G12: 28 | H12: =IF(F12=0,0,G12/F12) -> 1.1666667 | I12: Active | J12: QA cho 2 DA
A13: 10 | B13: Nguyễn Diên Sỹ Đạo | C13: Frontend Dev (Leader) | D13: CDS-2026-001
A14: 11 | B14: Đoàn Phan Kinh Kha | C14: Frontend Dev
A15: 12 | B15: Nguyễn Ngọc Bảo Quỳnh | C15: BA
A16: 13 | B16: Hoàng Hải Nam | C16: Backend Dev
A17: 14 | B17: Lâm Thu Đang | C17: QA/Tester
A18: 15 | B18: Trần Thị Ly | C18: QA/Tester
A19: 16 | B19: Nguyễn Trung Kiên | C19: DevOps
A20: 17 | B20: Huỳnh Thi | C20: Backend Dev/LMS/Marketing
A21: 18 | B21: Phùng Hoàng Anh | C21: Data Analyst | D21: CDS-2026-005 | E21: DevOps Engineer | F21: 32 | G21: 35 | H21: =IF(F21=0,0,G21/F21) -> 1.09375 | I21: Active | J21: Infra setup
A22: 19 | B22: Lê Thị Cẩm Tú | C22: BA
A23: 20
A24: 21
A25: TRUNG BÌNH | F25: =AVERAGE(F4:F21) -> 37.6 | G25: =AVERAGE(G4:G21) -> 34.9 | H25: =AVERAGE(H4:H21) -> 0.94104167
A45: MA TRẬN NHÂN SỰ x DỰ ÁN
A46: Nhân Sự \ Dự Án | B46: SmartShop - Sàn giao dịch TMDT | C46: Novagroup - Nền tảng eSales & eMarketing | D46: DuLichViet | E46: VietNamFoodMap - VCCA | F46: TPX - Sàn TMDT công nghệ | G46: AI CODE R&D
A47: Thái Hoàng Mai Học | B47: x | C47: x | D47: x | E47: x | F47: x | G47: x
A48: Nguyễn Hoàng Khan | B48: - | C48: x | D48: - | E48: - | F48: - | G48: x
A49: Lê Trần Anh Quí | B49: - | C49: x | E49: x | F49: - | G49: x
A50: Chung Chí Lâm | B50: x | C50: x | D50: - | E50: x | F50: x | G50: x
A51: Nguyễn Quang Khải | B51: - | C51: x | D51: - | E51: - | F51: - | G51: x
A52: Trịnh Hữu Thoại | B52: x | C52: x | D52: x | E52: x | F52: x | G52: x
A53: Hà Nhật Vềnh | B53: - | C53: x | D53: x | E53: x | F53: - | G53: x
A54: Nguyễn Nhất Sang | B54: - | C54: x | D54: x | E54: x | F54: - | G54: x
A55: Đinh Lê Trung Hiếu | B55: - | C55: x | D55: - | E55: - | F55: x | G55: x
A56: Nguyễn Diên Sỹ Đạo | B56: x | C56: x | D56: x | E56: x | F56: x | G56: x
A57: Đoàn Phan Kinh Kha | B57: x | C57: x | D57: - | E57: - | F57: - | G57: x
A58: Nguyễn Ngọc Bảo Quỳnh | B58: x | C58: x | D58: x | E58: - | F58: - | G58: x
A59: Hoàng Hải Nam | B59: x | C59: - | D59: - | E59: - | F59: - | G59: x
A60: Lâm Thu Đang | B60: x | C60: x | D60: - | E60: - | F60: - | G60: -
...

Sheet Rủi Ro & Vấn Đề
A1: QUẢN LÝ RỦI RO & VẤN ĐỀ DỰ ÁN
A3: STT | B3: Mã DA | C3: Tên Dự Án | D3: Mô Tả Rủi Ro / Vấn Đề | E3: Mức Nghiêm Trọng | F3: Xác Suất | G3: Mức Ảnh Hưởng | H3: Điểm Severity | I3: Điểm Probability | J3: Điểm Impact | K3: Risk Score | L3: Người Chịu TN | M3: Hành Động Giảm Thiểu | N3: Deadline | O3: Trạng Thái
A4: 1 | B4: CDS-2026-002 | C4: ERP Integration Gateway | D4: API vendor thay đổi spec không thông báo | E4: Critical | F4: Cao (70%) | G4: High | H4: =IFERROR(VLOOKUP(E4,Config!$A$20:$B$23,2,FALSE()),0) -> 4 | I4: =IF(ISNUMBER(SEARCH("Rất cao",F4)),5,IF(ISNUMBER(SEARCH("Cao",F4)),4,IF(ISNUMBER(SEARCH("Trung bình",F4)),3,IF(ISNUMBER(SEARCH("Thấp",F4)),2,IF(ISNUMBER(SEARCH("Rất thấp",F4)),1,0))))) -> 4 | J4: =IFERROR(VLOOKUP(G4,Config!$A$20:$B$23,2,FALSE()),0) -> 3 | K4: =H4*I4*J4 -> 48 | L4: Trần Thị Hương | M4: Escalate vendor, backup plan API wrapper | N4: 46101 | O4: Open
A5: 2 | B5: CDS-2026-005 | C5: Supply Chain Optimization | D5: Thiếu BA có kinh nghiệm supply chain | E5: High | F5: Rất cao (90%) | G5: High | H5: =IFERROR(VLOOKUP(E5,Config!$A$20:$B$23,2,FALSE()),0) -> 3 | I5: =IF(ISNUMBER(SEARCH("Rất cao",F5)),5,IF(ISNUMBER(SEARCH("Cao",F5)),4,IF(ISNUMBER(SEARCH("Trung bình",F5)),3,IF(ISNUMBER(SEARCH("Thấp",F5)),2,IF(ISNUMBER(SEARCH("Rất thấp",F5)),1,0))))) -> 5 | J5: =IFERROR(VLOOKUP(G5,Config!$A$20:$B$23,2,FALSE()),0) -> 3 | K5: =H5*I5*J5 -> 45 | L5: Nguyễn Thị Lan | M5: Tuyển BA freelance, training nội bộ | N5: 46106 | O5: In Progress
A6: 3 | B6: CDS-2026-005 | C6: Supply Chain Optimization | D6: Budget có thể vượt 15% do scope creep | E6: High | F6: Cao (70%) | G6: Critical | H6: =IFERROR(VLOOKUP(E6,Config!$A$20:$B$23,2,FALSE()),0) -> 3 | I6: =IF(ISNUMBER(SEARCH("Rất cao",F6)),5,IF(ISNUMBER(SEARCH("Cao",F6)),4,IF(ISNUMBER(SEARCH("Trung bình",F6)),3,IF(ISNUMBER(SEARCH("Thấp",F6)),2,IF(ISNUMBER(SEARCH("Rất thấp",F6)),1,0))))) -> 4 | J6: =IFERROR(VLOOKUP(G6,Config!$A$20:$B$23,2,FALSE()),0) -> 4 | K6: =H6*I6*J6 -> 48 | L6: Nguyễn Thị Lan | M6: Change request formal, freeze scope Phase 1 | N6: 46113 | O6: Open
A7: 4 | B7: CDS-2026-001 | C7: CDS Platform - Module Sales | D7: Performance bottleneck khi load >1000 concurrent users | E7: Medium | F7: Trung bình (50%) | G7: High | H7: =IFERROR(VLOOKUP(E7,Config!$A$20:$B$23,2,FALSE()),0) -> 2 | I7: =IF(ISNUMBER(SEARCH("Rất cao",F7)),5,IF(ISNUMBER(SEARCH("Cao",F7)),4,IF(ISNUMBER(SEARCH("Trung bình",F7)),3,IF(ISNUMBER(SEARCH("Thấp",F7)),2,IF(ISNUMBER(SEARCH("Rất thấp",F7)),1,0))))) -> 3 | J7: =IFERROR(VLOOKUP(G7,Config!$A$20:$B$23,2,FALSE()),0) -> 3 | K7: =H7*I7*J7 -> 18 | L7: Nguyễn Văn Minh | M7: Load testing, optimize query, caching | N7: 46127 | O7: In Progress
A8: 5 | B8: CDS-2026-006 | C8: Mobile App - Customer Portal | D8: iOS review policy thay đổi có thể delay release | E8: Medium | F8: Thấp (30%) | G8: Medium | H8: =IFERROR(VLOOKUP(E8,Config!$A$20:$B$23,2,FALSE()),0) -> 2 | I8: =IF(ISNUMBER(SEARCH("Rất cao",F8)),5,IF(ISNUMBER(SEARCH("Cao",F8)),4,IF(ISNUMBER(SEARCH("Trung bình",F8)),3,IF(ISNUMBER(SEARCH("Thấp",F8)),2,IF(ISNUMBER(SEARCH("Rất thấp",F8)),1,0))))) -> 2 | J8: =IFERROR(VLOOKUP(G8,Config!$A$20:$B$23,2,FALSE()),0) -> 2 | K8: =H8*I8*J8 -> 8 | L8: Hoàng Minh Tuấn | M8: Submit sớm, prepare documentation đầy đủ | N8: 46143 | O8: Open
A9: 6 | B9: CDS-2026-007 | C9: AI Chatbot Integration | D9: Model AI response chưa đạt accuracy 95% target | E9: High | F9: Trung bình (50%) | G9: High | H9: =IFERROR(VLOOKUP(E9,Config!$A$20:$B$23,2,FALSE()),0) -> 3 | I9: =IF(ISNUMBER(SEARCH("Rất cao",F9)),5,IF(ISNUMBER(SEARCH("Cao",F9)),4,IF(ISNUMBER(SEARCH("Trung bình",F9)),3,IF(ISNUMBER(SEARCH("Thấp",F9)),2,IF(ISNUMBER(SEARCH("Rất thấp",F9)),1,0))))) -> 3 | J9: =IFERROR(VLOOKUP(G9,Config!$A$20:$B$23,2,FALSE()),0) -> 3 | K9: =H9*I9*J9 -> 27 | L9: Võ Thanh Tùng | M9: Fine-tune model, expand training data | N9: 46188 | O9: Open
A10: 7 | B10: CDS-2026-002 | C10: ERP Integration Gateway | D10: Key developer có thể nghỉ việc | E10: Critical | F10: Trung bình (50%) | G10: Critical | H10: =IFERROR(VLOOKUP(E10,Config!$A$20:$B$23,2,FALSE()),0) -> 4 | I10: =IF(ISNUMBER(SEARCH("Rất cao",F10)),5,IF(ISNUMBER(SEARCH("Cao",F10)),4,IF(ISNUMBER(SEARCH("Trung bình",F10)),3,IF(ISNUMBER(SEARCH("Thấp",F10)),2,IF(ISNUMBER(SEARCH("Rất thấp",F10)),1,0))))) -> 3 | J10: =IFERROR(VLOOKUP(G10,Config!$A$20:$B$23,2,FALSE()),0) -> 4 | K10: =H10*I10*J10 -> 48 | L10: Trần Thị Hương | M10: Knowledge transfer, documentation, retention plan | N10: 46112 | O10: Escalated
A11: 8 | B11: CDS-2026-003 | C11: Data Analytics Dashboard | D11: Data quality từ source system không ổn định | E11: Medium | F11: Cao (70%) | G11: Medium | H11: =IFERROR(VLOOKUP(E11,Config!$A$20:$B$23,2,FALSE()),0) -> 2 | I11: =IF(ISNUMBER(SEARCH("Rất cao",F11)),5,IF(ISNUMBER(SEARCH("Cao",F11)),4,IF(ISNUMBER(SEARCH("Trung bình",F11)),3,IF(ISNUMBER(SEARCH("Thấp",F11)),2,IF(ISNUMBER(SEARCH("Rất thấp",F11)),1,0))))) -> 4 | J11: =IFERROR(VLOOKUP(G11,Config!$A$20:$B$23,2,FALSE()),0) -> 2 | K11: =H11*I11*J11 -> 16 | L11: Lê Quốc Bảo | M11: Data validation layer, ETL error handling | N11: 46122 | O11: In Progress
A13: TỔNG HỢP RỦI RO
A14: Tổng số rủi ro: | B14: =COUNTA(E4:E11) -> 8
A15: Critical: | B15: =COUNTIF(E4:E11,"Critical") -> 2
A16: High: | B16: =COUNTIF(E4:E11,"High") -> 3
A17: Open: | B17: =COUNTIF(O4:O11,"Open") -> 4
A18: Escalated: | B18: =COUNTIF(O4:O11,"Escalated") -> 1
A19: Risk Score TB: | B19: =AVERAGE(K4:K11) -> 32.25
A22: RISK MATRIX (Severity x Probability)
B23: Low (1) | C23: Medium (2) | D23: High (3) | E23: Critical (4)
A24: Rất cao (5) | B24: 5 | C24: 10 | D24: 15 | E24: 20
A25: Cao (4) | B25: 4 | C25: 8 | D25: 12 | E25: 16
A26: TB (3) | B26: 3 | C26: 6 | D26: 9 | E26: 12
A27: Thấp (2) | B27: 2 | C27: 4 | D27: 6 | E27: 8
A28: Rất thấp (1) | B28: 1 | C28: 2 | D28: 3 | E28: 4

Sheet Báo Cáo Tháng
A1: BÁO CÁO TỔNG HỢP THÁNG
A2: Kỳ: | B2: Tháng 3 | C2: Năm: | D2: 2026
A4: 1. TỔNG QUAN DỰ ÁN
A5: Tổng số dự án đang triển khai | B5: =COUNTIFS('Danh Sách Dự Án'!I5:I10,"<>Completed") -> 6
A6: Dự án On Track | B6: =COUNTIF('Danh Sách Dự Án'!I5:I10,"On Track") -> 3
A7: Dự án At Risk | B7: =COUNTIF('Danh Sách Dự Án'!I5:I10,"At Risk") -> 0
A8: Dự án Delayed | B8: =COUNTIF('Danh Sách Dự Án'!I5:I10,"Delayed") -> 2
A9: Dự án Completed | B9: =COUNTIF('Danh Sách Dự Án'!I5:I10,"Completed") -> 0
A10: % Dự án On Track | B10: =IFERROR(COUNTIF('Danh Sách Dự Án'!I5:I10,"On Track")/COUNTA('Danh Sách Dự Án'!I5:I10),0) -> 0.5
A11: % Hoàn thành trung bình | B11: ='Danh Sách Dự Án'!K11 -> 0.35833333
A13: 2. TÀI CHÍNH
A14: Tổng giá trị hợp đồng | B14: ='Danh Sách Dự Án'!M11 -> 11293500000
A15: Tổng đã thu | B15: ='Danh Sách Dự Án'!N11 -> 344500000
A16: Tổng còn phải thu | B16: ='Danh Sách Dự Án'!O11 -> 10949000000
A17: % Đã thu | B17: ='Danh Sách Dự Án'!P11 -> 0.030504272
A19: 3. RỦI RO CẦN XỬ LÝ
A20: Tổng số rủi ro đang mở | B20: =COUNTIFS('Rủi Ro & Vấn Đề'!O4:O11,"<>Resolved",'Rủi Ro & Vấn Đề'!O4:O11,"<>Closed") -> 8
A21: Rủi ro Critical | B21: =COUNTIF('Rủi Ro & Vấn Đề'!E4:E11,"Critical") -> 2
A22: Rủi ro đã Escalated | B22: =COUNTIF('Rủi Ro & Vấn Đề'!O4:O11,"Escalated") -> 1
A23: Risk Score trung bình | B23: =AVERAGE('Rủi Ro & Vấn Đề'!K4:K11) -> 32.25
A25: 4. NHÂN SỰ
A26: Tổng nhân sự tham gia DA | B26: ='Danh Sách Dự Án'!Q11 -> 55
A27: Utilization Rate trung bình | B27: ='Nhân Sự Dự Án'!H25 -> 0.94104167
A28: Nhân sự overloaded (>110%) | B28: =COUNTIF('Nhân Sự Dự Án'!H4:H21,">"&1.1) -> 2
A30: 5. HIGHLIGHTS
A31: 1. | B31: [Nhập highlight]
A32: 2. | B32: [Nhập highlight]
A33: 3. | B33: [Nhập highlight]
A34: 4.
A35: 5.
A37: 6. LOWLIGHTS / VẤN ĐỀ
A38: 1. | B38: [Nhập vấn đề]
A39: 2. | B39: [Nhập vấn đề]
A40: 3. | B40: [Nhập vấn đề]
A41: 4.
A42: 5.
A44: 7. ACTION ITEMS
A45: STT | B45: Action Item | C45: Người Phụ Trách | D45: Deadline | E45: Trạng Thái
A46: 1
A47: 2
...

Sheet Config
A1: CẤU HÌNH HỆ THỐNG
A3: Tháng | B3: Năm | C3: Trạng Thái Dự Án | D3: Mức Ưu Tiên | E3: Mức Nghiêm Trọng | F3: Trạng Thái Rủi Ro | G3: Xác Suất | H3: TT Thanh Toán
A4: Tháng 1 | B4: 2024 | C4: On Track | D4: Critical | E4: Critical | F4: Open | G4: Rất cao (90%) | H4: Đã thanh toán
A5: Tháng 2 | B5: 2025 | C5: At Risk | D5: High | E5: High | F5: In Progress | G5: Cao (70%) | H5: Chờ thanh toán
A6: Tháng 3 | B6: 2026 | C6: Delayed | D6: Medium | E6: Medium | F6: Resolved | G6: Trung bình (50%) | H6: Quá hạn
A7: Tháng 4 | B7: 2027 | C7: Completed | D7: Low | E7: Low | F7: Closed | G7: Thấp (30%) | H7: Chưa đến hạn
A8: Tháng 5 | B8: 2028 | C8: On Hold | F8: Escalated | G8: Rất thấp (10%)
A9: Tháng 6 | B9: 2029
A10: Tháng 7 | B10: 2030
A11: Tháng 8
A12: Tháng 9
A13: Tháng 10
A14: Tháng 11
A15: Tháng 12
A18: BẢNG QUY ĐỔI ĐIỂM RỦI RO
A19: Mức | B19: Điểm
A20: Critical | B20: 4
A21: High | B21: 3
A22: Medium | B22: 2
A23: Low | B23: 1
